using System.Diagnostics;
using AutoMapper;
using FriendlyGames.Api.Dtos;
using FriendlyGames.Api.Services;
using FriendlyGames.Api.Services.Interfaces;
using FriendlyGames.DataAccess;
using FriendlyGames.Domain.Models;
using Microsoft.AspNetCore.Authorization;
using Microsoft.AspNetCore.Mvc;
using Microsoft.EntityFrameworkCore;

namespace FriendlyGames.Api.Controllers;

[ApiController]
[Route("api/[controller]")]
public class EventsController : ControllerBase
{
    private readonly FriendlyGamesDbContext _dbContext;
    private readonly IEventService _eventService;
    private readonly ILogger<EventsController> _logger;
    private readonly IMapper _mapper;

    public EventsController(IMapper mapper, ILogger<EventsController> logger, FriendlyGamesDbContext dbContext,
        IEventService eventService)
    {
        _dbContext = dbContext;
        _mapper = mapper;
        _logger = logger;
        _eventService = eventService;
    }

    [HttpGet]
    [ProducesResponseType(StatusCodes.Status200OK)]
    [ProducesResponseType(StatusCodes.Status500InternalServerError)]
    public async Task<ActionResult<IEnumerable<EventsDto>>> GetEvents([FromQuery] int? categoryId,
        [FromQuery] string? levelCategoryIds,
        [FromQuery] string? surfaceCategoryIds, [FromQuery] string? surroundingCategoryIds, [FromQuery] string? payable)
    {
        _logger.LogInformation($"{nameof(GetEvents)} called...");

        try
        {
            var results = await _eventService.GetEvents(categoryId, levelCategoryIds, surfaceCategoryIds,
                surroundingCategoryIds, payable);

            return Ok(results);
        }
        catch (Exception exception)
        {
            _logger.LogError(exception, $"Something went wrong in {nameof(GetEvents)}");

            return Problem("Internal server error, please try again later...");
        }
    }

    [HttpGet("{id:int}", Name = "GetEvent")]
    [ProducesResponseType(StatusCodes.Status200OK)]
    [ProducesResponseType(StatusCodes.Status404NotFound)]
    [ProducesResponseType(StatusCodes.Status500InternalServerError)]
    public async Task<ActionResult<EventsDto>> GetEvent(int id)
    {
        _logger.LogInformation($"{nameof(GetEvent)} called...");

        try
        {
            var registrations = await (_dbContext.Registrations ?? throw new InvalidOperationException())
                .Include(x => x.ApiUser)
                .Where(e => e.EventId == id).ToListAsync();

            var specificEvent = await (_dbContext.Events ?? throw new InvalidOperationException())
                .Include(x => x.ApiUser)
                .Include(x => x.EventCategory)
                .Include(x => x.Registrations)
                .Include(x => x.LevelCategory)
                .Include(x => x.SurfaceCategory)
                .Include(x => x.SurroundingCategory)
                .FirstOrDefaultAsync(e => e.Id == id);

            if (specificEvent == null) return NotFound("Not found that specific event");

            specificEvent.Registrations = registrations;

            return Ok(specificEvent);
        }
        catch (Exception exception)
        {
            _logger.LogError(exception, $"Something went wrong in {nameof(GetEvent)}");

            return Problem("Internal server error, please try again later...");
        }
    }

    [HttpPost]
    [Authorize(Roles = "User")]
    [ProducesResponseType(StatusCodes.Status201Created)]
    [ProducesResponseType(StatusCodes.Status400BadRequest)]
    [ProducesResponseType(StatusCodes.Status500InternalServerError)]
    public async Task<IActionResult> CreateEvent([FromBody] EventCreateUpdateDto eventCreateUpdateDto)
    {
        _logger.LogInformation($"{nameof(CreateEvent)} called...");

        if (!ModelState.IsValid)
        {
            _logger.LogError($"Invalid POST attempt in {nameof(CreateEvent)}");

            return BadRequest(ModelState);
        }

        try
        {
            var newEvent = _mapper.Map<Event>(eventCreateUpdateDto);
            Debug.Assert(_dbContext.Events != null, "_dbContext.Events != null");
            await _dbContext.Events.AddAsync(newEvent);
            await _dbContext.SaveChangesAsync();

            return CreatedAtRoute("GetEvent", new {id = newEvent.Id}, newEvent);
        }
        catch (Exception exception)
        {
            _logger.LogError(exception, $"Something went wrong in {nameof(CreateEvent)}");
            return Problem("Internal server error, please try again later...");
        }
    }

    [HttpPut("{id:int}")]
    [Authorize(Roles = "User")]
    [ProducesResponseType(StatusCodes.Status204NoContent)]
    [ProducesResponseType(StatusCodes.Status400BadRequest)]
    [ProducesResponseType(StatusCodes.Status500InternalServerError)]
    public async Task<IActionResult> UpdateEvent([FromBody] EventCreateUpdateDto eventUpdateDto, int id)
    {
        _logger.LogInformation($"{nameof(UpdateEvent)} called...");

        if (!ModelState.IsValid)
        {
            _logger.LogError($"Invalid PUT attempt in {nameof(CreateEvent)}");
            return BadRequest(ModelState);
        }

        try
        {
            var eventToEdit = await (_dbContext.Events ?? throw new InvalidOperationException())
                .FirstOrDefaultAsync(e => e.Id == id);

            if (eventToEdit == null) return BadRequest("Submitted data is invalid!");
            _mapper.Map(eventUpdateDto, eventToEdit);

            await _dbContext.SaveChangesAsync();

            return Ok(eventUpdateDto);
        }
        catch (Exception exception)
        {
            _logger.LogError(exception, $"Something went wrong in {nameof(UpdateEvent)}");
            return Problem("Internal server error, please try again later...");
        }
    }

    [HttpDelete("{id:int}")]
    [Authorize(Roles = "User")]
    [ProducesResponseType(StatusCodes.Status204NoContent)]
    [ProducesResponseType(StatusCodes.Status404NotFound)]
    [ProducesResponseType(StatusCodes.Status400BadRequest)]
    [ProducesResponseType(StatusCodes.Status500InternalServerError)]
    public async Task<IActionResult> DeleteEvent(int id)
    {
        _logger.LogInformation($"{nameof(DeleteEvent)} called...");

        if (id < 1)
        {
            _logger.LogError($"Invalid DELETE attempt in {nameof(DeleteEvent)}");

            return BadRequest();
        }

        try
        {
            var registrations = await (_dbContext.Registrations ?? throw new InvalidOperationException())
                .Include(x => x.ApiUser)
                .Where(e => e.EventId == id).ToListAsync();

            var specificEvent = await (_dbContext.Events ?? throw new InvalidOperationException())
                .Include(x => x.ApiUser)
                .Include(x => x.EventCategory)
                .Include(x => x.Registrations)
                .Include(x => x.LevelCategory)
                .Include(x => x.SurfaceCategory)
                .Include(x => x.SurroundingCategory)
                .FirstOrDefaultAsync(x => x.Id == id);

            if (specificEvent == null) return NotFound($"There is no event with id = {id}");

            foreach (var registration in registrations) _dbContext.Registrations.Remove(registration);
            _dbContext.Events.Remove(specificEvent);
            await _dbContext.SaveChangesAsync();

            return NoContent();
        }
        catch (Exception exception)
        {
            _logger.LogError(exception, $"Something went wrong in {nameof(DeleteEvent)}");

            return Problem("Internal server error, please try again later...");
        }
    }
}